Workbook

Sheet Đọc trước
A1: Gói dữ liệu luật TM — evfta.eu MVP, bản v0 (30/9/2026)
A2: Người soạn | B2: Claude (vai chuyên viên luật TM, soạn thảo). Cột reviewed_by để trống: người duyệt là người thật, chịu trách nhiệm pháp lý.
A3: Trạng thái | B3: DỰ THẢO. Không dòng nào được hiện ra ngoài trước khi có reviewed_by + reviewed_at (quy tắc C1).
A4: Độ tin cậy dữ liệu (cột 'confidence') | B4: A = đã thấy trong nguồn chính thức/Bộ Công Thương; B = nguồn thứ cấp uy tín, cần đối chiếu văn bản gốc; C = soạn từ hiểu biết chuyên môn, BẮT BUỘC đối chiếu TARIC/Phụ lục 2-A-1/Phụ lục II NĐT1 trước khi duyệt.
A5: Nội dung | B5: hs_codes_20 (C0) · tariff_lines (C1) · psr_rules (C4) · c4_test_cases (C4) · eur1_fields (C5/Q8) · corpus_manifest (D0) · copilot_50 (D4, bản đầy đủ ở copilot_50.jsonl) · cau_hoi_mo (việc người duyệt phải chốt).
A6: Cách tính thuế EVFTA 2026 | B6: Năm 1 = 2020 (hiệu lực 1/8/2020), năm 2026 = năm 7. Nhóm A về 0 ngay; B3 (4 đợt), B5 (6 đợt) đã về 0 trước 2026; B7 (8 đợt) năm 2026 còn 1/8 thuế cơ sở, về 0 từ 1/1/2027. Công thức ở cột evfta_rate_2026 tự tính từ base_rate + staging_category. Quy tắc làm tròn mức trung gian: cần đối chiếu Phụ lục 2-A.
A7: Ô chữ xanh dương | B7: Giá trị người duyệt cần kiểm/sửa. Ô nền vàng = chưa có dữ liệu, phải tra.
A8: Nguyên tắc | B8: Không đoán. Dòng nào chưa chắc: để trống + ghi rõ cần tra gì, thay vì điền số gần đúng.

Sheet hs_codes_20
A1: code (6 số) | B1: cn8 (dòng EU) | C1: name_vi | D1: name_en | E1: chapter | F1: nhóm hàng | G1: lý do chọn | H1: độ khó duyệt | I1: is_calculator_supported | J1: reviewed_by | K1: reviewed_at
A2: 0306.17 | B2: 0306 17 99 | C2: Tôm đông lạnh (khác) | D2: Frozen shrimps and prawns, other | E2: 03 | F2: Thủy sản | G2: Kim ngạch EUR.1 lớn nhất ngành thủy sản; ví dụ 'tiết kiệm 12%' rõ | H2: Dễ | I2: TRUE
A3: 1605.21 | B3: 1605 21 90 | C3: Tôm chế biến, không đóng kín khí | D3: Shrimps and prawns, prepared, not in airtight container | E3: 16 | F3: Thủy sản | G3: Kim ngạch EUR.1 lớn; còn thuế năm 2026 nếu là B7 | H3: Trung bình | I3: TRUE
A4: 1605.29 | B4: 1605 29 00 | C4: Tôm chế biến, khác | D4: Shrimps and prawns, prepared, other | E4: 16 | F4: Thủy sản | G4: Như trên | H4: Trung bình | I4: TRUE
A5: 0304.62 | B5: 0304 62 00 | C5: Phi lê cá tra/basa đông lạnh | D5: Frozen fillets of catfish (Pangasius) | E5: 03 | F5: Thủy sản | G5: Tỷ lệ dùng C/O cao nhất (87%) | H5: Dễ | I5: TRUE
A6: 0304.87 | B6: 0304 87 00 | C6: Phi lê cá ngừ đông lạnh | D6: Frozen fillets of tuna | E6: 03 | F6: Thủy sản | G6: Thuế cơ sở 18%, lộ trình đã rõ | H6: Dễ | I6: TRUE
A7: 1604.14 | B7: 1604 14 xx | C7: Cá ngừ đóng hộp | D7: Prepared or preserved tuna | E7: 16 | F7: Thủy sản | G7: Ca hạn ngạch 11.500 tấn → kiểm tra hành vi 'cần kiểm thêm' | H7: Khó (TRQ) | I7: TRUE (trả 'cần kiểm thêm')
A8: 0307.43 | B8: 0307 43 xx | C8: Mực đông lạnh | D8: Frozen cuttlefish and squid | E8: 03 | F8: Thủy sản | G8: Xóa thuế ngay; dòng 8 số cần chọn đúng | H8: Dễ | I8: TRUE
A9: 0901.11 | B9: 0901 11 00 | C9: Cà phê nhân chưa rang | D9: Coffee, not roasted, not decaffeinated | E9: 09 | F9: Nông sản | G9: MFN 0% → ca 'không có chênh lệch thuế', chống quảng cáo sai | H9: Dễ | I9: TRUE
A10: 0901.21 | B10: 0901 21 00 | C10: Cà phê rang | D10: Coffee, roasted, not decaffeinated | E10: 09 | F10: Nông sản | G10: Ca có chênh lệch thật trong nhóm cà phê | H10: Dễ | I10: TRUE
A11: 2101.11 | B11: 2101 11 00 | C11: Cà phê hòa tan/chiết xuất | D11: Extracts, essences, concentrates of coffee | E11: 21 | F11: Thực phẩm | G11: Sản phẩm SIAL điển hình | H11: Trung bình | I11: TRUE
A12: 0904.11 | B12: 0904 11 00 | C12: Hạt tiêu chưa xay | D12: Pepper, neither crushed nor ground | E12: 09 | F12: Nông sản | G12: MFN 0% → ca không chênh lệch | H12: Dễ | I12: TRUE
A13: 0801.32 | B13: 0801 32 00 | C13: Hạt điều nhân | D13: Cashew nuts, shelled | E13: 08 | F13: Nông sản | G13: MFN 0% → ca không chênh lệch | H13: Dễ | I13: TRUE
... A21: 9403.60 | B21: 9403 60 xx | C21: Đồ nội thất gỗ | D21: Other wooden furniture | E21: 94 | F21: Gỗ | G21: MFN 0% → ca không chênh lệch; ngành xuất khẩu lớn | H21: Dễ | I21: TRUE

Sheet tariff_lines
A1: hs_code | B1: cn8 | C1: destination | D1: duty_type | E1: base_rate_pct (MFN cơ sở) | F1: staging_category | G1: evfta_rate_2026_pct (tự tính) | H1: savings_pct_points (tự tính) | I1: zero_from | J1: quota_required | K1: condition_note | L1: source | M1: confidence | N1: reviewed_by | O1: reviewed_at | P1: valid_from | Q1: valid_until
A2: 0306.17 | B2: 0306 17 91–99 | C2: EU-27 | D2: ad_valorem | E2: 12 | F2: A | G2: =IF(OR(E2="",F2="",F2="TRQ",D2<>"ad_valorem"),"cần kiểm thêm",IF(F2="A",0,E2*MAX(0,INDEX(staging!$B$2:$B$5,MATCH(F2,staging!$A$2:$A$5,0))-staging!$E$2)/INDEX(staging!$B$2:$B$5,MATCH(F2,staging!$A$2:$A$5,0)))) -> 0 | H2: =IF(ISNUMBER(G2),E2-G2,"") -> 12 | I2: =IF(F2="A","2020-08-01",IF(ISNUMBER(MATCH(F2,staging!$A$2:$A$5,0)),(2020+INDEX(staging!$B$2:$B$5,MATCH(F2,staging!$A$2:$A$5,0))-1)&"-01-01","")) -> 2020-08-01 | J2: FALSE | K2: Dòng 0306 17 10 có mức cơ sở khác — không gộp | L2: Bộ Công Thương (moit.gov.vn) — cam kết thuế thủy sản EVFTA | M2: A | P2: 2026-01-01 | Q2: 2026-12-31
A3: 1605.21 | B3: 1605 21 90 | C3: EU-27 | D3: ad_valorem | E3: 20 | F3: B7 | G3: =IF(OR(E3="",F3="",F3="TRQ",D3<>"ad_valorem"),"cần kiểm thêm",IF(F3="A",0,E3*MAX(0,INDEX(staging!$B$2:$B$5,MATCH(F3,staging!$A$2:$A$5,0))-staging!$E$2)/INDEX(staging!$B$2:$B$5,MATCH(F3,staging!$A$2:$A$5,0)))) -> 2.5 | H3: =IF(ISNUMBER(G3),E3-G3,"") -> 17.5 | I3: =IF(F3="A","2020-08-01",IF(ISNUMBER(MATCH(F3,staging!$A$2:$A$5,0)),(2020+INDEX(staging!$B$2:$B$5,MATCH(F3,staging!$A$2:$A$5,0))-1)&"-01-01","")) -> 2027-01-01 | J3: FALSE | K3: Nếu đúng B7: 2026 còn 1/8 cơ sở, 0% từ 1/1/2027 | L3: Cẩm nang thủy sản Bộ Công Thương 2024 (mức 20% → 0%); lộ trình cần tra 2-A-1 | M3: B | P3: 2026-01-01 | Q3: 2026-12-31
A4: 1605.29 | B4: 1605 29 00 | C4: EU-27 | D4: ad_valorem | E4: 20 | F4: B7 | G4: =IF(OR(E4="",F4="",F4="TRQ",D4<>"ad_valorem"),"cần kiểm thêm",IF(F4="A",0,E4*MAX(0,INDEX(staging!$B$2:$B$5,MATCH(F4,staging!$A$2:$A$5,0))-staging!$E$2)/INDEX(staging!$B$2:$B$5,MATCH(F4,staging!$A$2:$A$5,0)))) -> 2.5 | H4: =IF(ISNUMBER(G4),E4-G4,"") -> 17.5 | I4: =IF(F4="A","2020-08-01",IF(ISNUMBER(MATCH(F4,staging!$A$2:$A$5,0)),(2020+INDEX(staging!$B$2:$B$5,MATCH(F4,staging!$A$2:$A$5,0))-1)&"-01-01","")) -> 2027-01-01 | J4: FALSE | K4: Như 1605.21 | L4: Như trên | M4: C | P4: 2026-01-01 | Q4: 2026-12-31
A5: 0304.62 | B5: 0304 62 00 | C5: EU-27 | D5: ad_valorem | E5: 9 | F5: B3 | G5: =IF(OR(E5="",F5="",F5="TRQ",D5<>"ad_valorem"),"cần kiểm thêm",IF(F5="A",0,E5*MAX(0,INDEX(staging!$B$2:$B$5,MATCH(F5,staging!$A$2:$A$5,0))-staging!$E$2)/INDEX(staging!$B$2:$B$5,MATCH(F5,staging!$A$2:$A$5,0)))) -> 0 | H5: =IF(ISNUMBER(G5),E5-G5,"") -> 9 | I5: =IF(F5="A","2020-08-01",IF(ISNUMBER(MATCH(F5,staging!$A$2:$A$5,0)),(2020+INDEX(staging!$B$2:$B$5,MATCH(F5,staging!$A$2:$A$5,0))-1)&"-01-01","")) -> 2023-01-01 | J5: FALSE | K5: Đã 0% từ 2023 nếu đúng B3 | L5: Thông tin lộ trình cá tra 3–7 năm (Bộ Công Thương); mức/nhóm cần tra | M5: C | P5: 2026-01-01 | Q5: 2026-12-31
A6: 0304.87 | B6: 0304 87 00 | C6: EU-27 | D6: ad_valorem | E6: 18 | F6: B3 | G6: =IF(OR(E6="",F6="",F6="TRQ",D6<>"ad_valorem"),"cần kiểm thêm",IF(F6="A",0,E6*MAX(0,INDEX(staging!$B$2:$B$5,MATCH(F6,staging!$A$2:$A$5,0))-staging!$E$2)/INDEX(staging!$B$2:$B$5,MATCH(F6,staging!$A$2:$A$5,0)))) -> 0 | H6: =IF(ISNUMBER(G6),E6-G6,"") -> 18 | I6: =IF(F6="A","2020-08-01",IF(ISNUMBER(MATCH(F6,staging!$A$2:$A$5,0)),(2020+INDEX(staging!$B$2:$B$5,MATCH(F6,staging!$A$2:$A$5,0))-1)&"-01-01","")) -> 2023-01-01 | J6: FALSE | K6: Lộ trình '3 năm' (truyền thông) = nhóm B3 (4 đợt) | L6: Bộ Công Thương — thủy sản EVFTA | M6: A | P6: 2026-01-01 | Q6: 2026-12-31
A7: 1604.14 | B7: 1604 14 xx | C7: EU-27 | D7: ad_valorem | E7: 24 | F7: TRQ | G7: =IF(OR(E7="",F7="",F7="TRQ",D7<>"ad_valorem"),"cần kiểm thêm",IF(F7="A",0,E7*MAX(0,INDEX(staging!$B$2:$B$5,MATCH(F7,staging!$A$2:$A$5,0))-staging!$E$2)/INDEX(staging!$B$2:$B$5,MATCH(F7,staging!$A$2:$A$5,0)))) -> cần kiểm thêm | H7: =IF(ISNUMBER(G7),E7-G7,"") | I7: =IF(F7="A","2020-08-01",IF(ISNUMBER(MATCH(F7,staging!$A$2:$A$5,0)),(2020+INDEX(staging!$B$2:$B$5,MATCH(F7,staging!$A$2:$A$5,0))-1)&"-01-01","")) | J7: TRUE | K7: 0% trong hạn ngạch 11.500 tấn/năm; ngoài hạn ngạch = MFN. Công cụ phải trả 'cần kiểm thêm' | L7: Bộ Công Thương — thủy sản EVFTA | M7: A | P7: 2026-01-01 | Q7: 2026-12-31
A8: 0307.43 | B8: 0307 43 xx | C8: EU-27 | D8: ad_valorem | E8: 8 | F8: A | G8: =IF(OR(E8="",F8="",F8="TRQ",D8<>"ad_valorem"),"cần kiểm thêm",IF(F8="A",0,E8*MAX(0,INDEX(staging!$B$2:$B$5,MATCH(F8,staging!$A$2:$A$5,0))-staging!$E$2)/INDEX(staging!$B$2:$B$5,MATCH(F8,staging!$A$2:$A$5,0)))) -> 0 | H8: =IF(ISNUMBER(G8),E8-G8,"") -> 8 | I8: =IF(F8="A","2020-08-01",IF(ISNUMBER(MATCH(F8,staging!$A$2:$A$5,0)),(2020+INDEX(staging!$B$2:$B$5,MATCH(F8,staging!$A$2:$A$5,0))-1)&"-01-01","")) -> 2020-08-01 | J8: FALSE | K8: Chọn đúng dòng 8 số (Loligo khác mức) | L8: Bộ Công Thương (mực: xóa thuế ngay); MFN cần tra | M8: B | P8: 2026-01-01 | Q8: 2026-12-31
A9: 0901.11 | B9: 0901 11 00 | C9: EU-27 | D9: ad_valorem | E9: 0 | F9: A | G9: =IF(OR(E9="",F9="",F9="TRQ",D9<>"ad_valorem"),"cần kiểm thêm",IF(F9="A",0,E9*MAX(0,INDEX(staging!$B$2:$B$5,MATCH(F9,staging!$A$2:$A$5,0))-staging!$E$2)/INDEX(staging!$B$2:$B$5,MATCH(F9,staging!$A$2:$A$5,0)))) -> 0 | H9: =IF(ISNUMBER(G9),E9-G9,"") -> 0 | I9: =IF(F9="A","2020-08-01",IF(ISNUMBER(MATCH(F9,staging!$A$2:$A$5,0)),(2020+INDEX(staging!$B$2:$B$5,MATCH(F9,staging!$A$2:$A$5,0))-1)&"-01-01","")) -> 2020-08-01 | J9: FALSE | K9: MFN 0% → tiết kiệm = 0; công cụ phải nói rõ | L9: CN/TARIC — cần tra | M9: C | P9: 2026-01-01 | Q9: 2026-12-31
A10: 0901.21 | B10: 0901 21 00 | C10: EU-27 | D10: ad_valorem | E10: 7.5 | F10: A | G10: =IF(OR(E10="",F10="",F10="TRQ",D10<>"ad_valorem"),"cần kiểm thêm",IF(F10="A",0,E10*MAX(0,INDEX(staging!$B$2:$B$5,MATCH(F10,staging!$A$2:$A$5,0))-staging!$E$2)/INDEX(staging!$B$2:$B$5,MATCH(F10,staging!$A$2:$A$5,0)))) -> 0 | H10: =IF(ISNUMBER(G10),E10-G10,"") -> 7.5 | I10: =IF(F10="A","2020-08-01",IF(ISNUMBER(MATCH(F10,staging!$A$2:$A$5,0)),(2020+INDEX(staging!$B$2:$B$5,MATCH(F10,staging!$A$2:$A$5,0))-1)&"-01-01","")) -> 2020-08-01 | J10: FALSE | L10: CN/TARIC — cần tra | M10: C | P10: 2026-01-01 | Q10: 2026-12-31
A11: 2101.11 | B11: 2101 11 00 | C11: EU-27 | D11: ad_valorem | E11: 9 | G11: =IF(OR(E11="",F11="",F11="TRQ",D11<>"ad_valorem"),"cần kiểm thêm",IF(F11="A",0,E11*MAX(0,INDEX(staging!$B$2:$B$5,MATCH(F11,staging!$A$2:$A$5,0))-staging!$E$2)/INDEX(staging!$B$2:$B$5,MATCH(F11,staging!$A$2:$A$5,0)))) -> cần kiểm thêm | H11: =IF(ISNUMBER(G11),E11-G11,"") | I11: =IF(F11="A","2020-08-01",IF(ISNUMBER(MATCH(F11,staging!$A$2:$A$5,0)),(2020+INDEX(staging!$B$2:$B$5,MATCH(F11,staging!$A$2:$A$5,0))-1)&"-01-01","")) | J11: FALSE | K11: Nhóm lộ trình chưa xác định | L11: CN/TARIC + 2-A-1 — cần tra | M11: C | P11: 2026-01-01 | Q11: 2026-12-31
A12: 0904.11 | B12: 0904 11 00 | C12: EU-27 | D12: ad_valorem | E12: 0 | F12: A | G12: =IF(OR(E12="",F12="",F12="TRQ",D12<>"ad_valorem"),"cần kiểm thêm",IF(F12="A",0,E12*MAX(0,INDEX(staging!$B$2:$B$5,MATCH(F12,staging!$A$2:$A$5,0))-staging!$E$2)/INDEX(staging!$B$2:$B$5,MATCH(F12,staging!$A$2:$A$5,0)))) -> 0 | H12: =IF(ISNUMBER(G12),E12-G12,"") -> 0 | I12: =IF(F12="A","2020-08-01",IF(ISNUMBER(MATCH(F12,staging!$A$2:$A$5,0)),(2020+INDEX(staging!$B$2:$B$5,MATCH(F12,staging!$A$2:$A$5,0))-1)&"-01-01","")) -> 2020-08-01 | J12: FALSE | K12: MFN 0% → tiết kiệm = 0 | L12: CN/TARIC — cần tra | M12: C | P12: 2026-01-01 | Q12: 2026-12-31
A13: 0801.32 | B13: 0801 32 00 | C13: EU-27 | D13: ad_valorem | E13: 0 | F13: A | G13: =IF(OR(E13="",F13="",F13="TRQ",D13<>"ad_valorem"),"cần kiểm thêm",IF(F13="A",0,E13*MAX(0,INDEX(staging!$B$2:$B$5,MATCH(F13,staging!$A$2:$A$5,0))-staging!$E$2)/INDEX(staging!$B$2:$B$5,MATCH(F13,staging!$A$2:$A$5,0)))) -> 0 | H13: =IF(ISNUMBER(G13),E13-G13,"") -> 0 | I13: =IF(F13="A","2020-08-01",IF(ISNUMBER(MATCH(F13,staging!$A$2:$A$5,0)),(2020+INDEX(staging!$B$2:$B$5,MATCH(F13,staging!$A$2:$A$5,0))-1)&"-01-01","")) -> 2020-08-01 | J13: FALSE | K13: MFN 0% → tiết kiệm = 0 | L13: CN/TARIC — cần tra | M13: C | P13: 2026-01-01 | Q13: 2026-12-31
A14: 0810.90 | B14: 0810 90 20 | C14: EU-27 | D14: ad_valorem | E14: 0 | F14: A | G14: =IF(OR(E14="",F14="",F14="TRQ",D14<>"ad_valorem"),"cần kiểm thêm",IF(F14="A",0,E14*MAX(0,INDEX(staging!$B$2:$B$5,MATCH(F14,staging!$A$2:$A$5,0))-staging!$E$2)/INDEX(staging!$B$2:$B$5,MATCH(F14,staging!$A$2:$A$5,0)))) -> 0 | H14: =IF(ISNUMBER(G14),E14-G14,"") -> 0 | I14: =IF(F14="A","2020-08-01",IF(ISNUMBER(MATCH(F14,staging!$A$2:$A$5,0)),(2020+INDEX(staging!$B$2:$B$5,MATCH(F14,staging!$A$2:$A$5,0))-1)&"-01-01","")) -> 2020-08-01 | J14: FALSE | K14: Nếu MFN 0% thì câu 'thanh long được giảm thuế nhờ EVFTA' là sai — kiểm kỹ | L14: CN/TARIC — cần tra | M14: C | P14: 2026-01-01 | Q14: 2026-12-31
A15: 1006.30 | B15: 1006 30 xx | C15: EU-27 | D15: specific | F15: TRQ | G15: =IF(OR(E15="",F15="",F15="TRQ",D15<>"ad_valorem"),"cần kiểm thêm",IF(F15="A",0,E15*MAX(0,INDEX(staging!$B$2:$B$5,MATCH(F15,staging!$A$2:$A$5,0))-staging!$E$2)/INDEX(staging!$B$2:$B$5,MATCH(F15,staging!$A$2:$A$5,0)))) -> cần kiểm thêm | H15: =IF(ISNUMBER(G15),E15-G15,"") | I15: =IF(F15="A","2020-08-01",IF(ISNUMBER(MATCH(F15,staging!$A$2:$A$5,0)),(2020+INDEX(staging!$B$2:$B$5,MATCH(F15,staging!$A$2:$A$5,0))-1)&"-01-01","")) | J15: TRUE | K15: MFN tính theo EUR/tấn. Hạn ngạch tổng 80.000 tấn/năm; gạo thơm chỉ các giống liệt kê — ST25 không thuộc danh sách theo ghi nhận hiện có. Công cụ KHÔNG ra 0% | L15: USDA FAS (80.000 tấn); danh sách giống: 2-A-1 + NĐ 103/2020 | M15: B | P15: 2026-01-01 | Q15: 2026-12-31
A16: 1905.90 | B16: 1905 90 xx | C16: EU-27 | D16: mixed | G16: =IF(OR(E16="",F16="",F16="TRQ",D16<>"ad_valorem"),"cần kiểm thêm",IF(F16="A",0,E16*MAX(0,INDEX(staging!$B$2:$B$5,MATCH(F16,staging!$A$2:$A$5,0))-staging!$E$2)/INDEX(staging!$B$2:$B$5,MATCH(F16,staging!$A$2:$A$5,0)))) -> cần kiểm thêm | H16: =IF(ISNUMBER(G16),E16-G16,"") | I16: =IF(F16="A","2020-08-01",IF(ISNUMBER(MATCH(F16,staging!$A$2:$A$5,0)),(2020+INDEX(staging!$B$2:$B$5,MATCH(F16,staging!$A$2:$A$5,0))-1)&"-01-01","")) | J16: FALSE | K16: Thuế hỗn hợp (ad valorem + thành phần nông nghiệp EA) → 'cần kiểm thêm' | L16: CN/TARIC — cần tra | M16: C | P16: 2026-01-01 | Q16: 2026-12-31
A17: 6109.10 | B17: 6109 10 00 | C17: EU-27 | D17: ad_valorem | E17: 12 | G17: =IF(OR(E17="",F17="",F17="TRQ",D17<>"ad_valorem"),"cần kiểm thêm",IF(F17="A",0,E17*MAX(0,INDEX(staging!$B$2:$B$5,MATCH(F17,staging!$A$2:$A$5,0))-staging!$E$2)/INDEX(staging!$B$2:$B$5,MATCH(F17,staging!$A$2:$A$5,0)))) -> cần kiểm thêm | H17: =IF(ISNUMBER(G17),E17-G17,"") | I17: =IF(F17="A","2020-08-01",IF(ISNUMBER(MATCH(F17,staging!$A$2:$A$5,0)),(2020+INDEX(staging!$B$2:$B$5,MATCH(F17,staging!$A$2:$A$5,0))-1)&"-01-01","")) | J17: FALSE | K17: Nhóm lộ trình chưa xác định — không đoán | L17: Thuế cơ sở may mặc 12% (Tạp chí Kinh tế & Dự báo); lộ trình cần tra 2-A-1 | M17: B | P17: 2026-01-01 | Q17: 2026-12-31
A18: 6203.42 | B18: 6203 42 xx | C18: EU-27 | D18: ad_valorem | E18: 12 | G18: =IF(OR(E18="",F18="",F18="TRQ",D18<>"ad_valorem"),"cần kiểm thêm",IF(F18="A",0,E18*MAX(0,INDEX(staging!$B$2:$B$5,MATCH(F18,staging!$A$2:$A$5,0))-staging!$E$2)/INDEX(staging!$B$2:$B$5,MATCH(F18,staging!$A$2:$A$5,0)))) -> cần kiểm thêm | H18: =IF(ISNUMBER(G18),E18-G18,"") | I18: =IF(F18="A","2020-08-01",IF(ISNUMBER(MATCH(F18,staging!$A$2:$A$5,0)),(2020+INDEX(staging!$B$2:$B$5,MATCH(F18,staging!$A$2:$A$5,0))-1)&"-01-01","")) | J18: FALSE | K18: Như trên | L18: Như trên | M18: B | P18: 2026-01-01 | Q18: 2026-12-31
A19: 6403.99 | B19: 6403 99 xx | C19: EU-27 | D19: ad_valorem | E19: 8 | G19: =IF(OR(E19="",F19="",F19="TRQ",D19<>"ad_valorem"),"cần kiểm thêm",IF(F19="A",0,E19*MAX(0,INDEX(staging!$B$2:$B$5,MATCH(F19,staging!$A$2:$A$5,0))-staging!$E$2)/INDEX(staging!$B$2:$B$5,MATCH(F19,staging!$A$2:$A$5,0)))) -> cần kiểm thêm | H19: =IF(ISNUMBER(G19),E19-G19,"") | I19: =IF(F19="A","2020-08-01",IF(ISNUMBER(MATCH(F19,staging!$A$2:$A$5,0)),(2020+INDEX(staging!$B$2:$B$5,MATCH(F19,staging!$A$2:$A$5,0))-1)&"-01-01","")) | J19: FALSE | K19: Một số dòng 6403 99 có mức khác | L19: CN/TARIC + 2-A-1 — cần tra | M19: C | P19: 2026-01-01 | Q19: 2026-12-31
A20: 6404.11 | B20: 6404 11 00 | C20: EU-27 | D20: ad_valorem | E20: 16.9 | G20: =IF(OR(E20="",F20="",F20="TRQ",D20<>"ad_valorem"),"cần kiểm thêm",IF(F20="A",0,E20*MAX(0,INDEX(staging!$B$2:$B$5,MATCH(F20,staging!$A$2:$A$5,0))-staging!$E$2)/INDEX(staging!$B$2:$B$5,MATCH(F20,staging!$A$2:$A$5,0)))) -> cần kiểm thêm | H20: =IF(ISNUMBER(G20),E20-G20,"") | I20: =IF(F20="A","2020-08-01",IF(ISNUMBER(MATCH(F20,staging!$A$2:$A$5,0)),(2020+INDEX(staging!$B$2:$B$5,MATCH(F20,staging!$A$2:$A$5,0))-1)&"-01-01","")) | J20: FALSE | L20: CN/TARIC + 2-A-1 — cần tra | M20: C | P20: 2026-01-01 | Q20: 2026-12-31
A21: 9403.60 | B21: 9403 60 xx | C21: EU-27 | D21: ad_valorem | E21: 0 | F21: A | G21: =IF(OR(E21="",F21="",F21="TRQ",D21<>"ad_valorem"),"cần kiểm thêm",IF(F21="A",0,E21*MAX(0,INDEX(staging!$B$2:$B$5,MATCH(F21,staging!$A$2:$A$5,0))-staging!$E$2)/INDEX(staging!$B$2:$B$5,MATCH(F21,staging!$A$2:$A$5,0)))) -> 0 | H21: =IF(ISNUMBER(G21),E21-G21,"") -> 0 | I21: =IF(F21="A","2020-08-01",IF(ISNUMBER(MATCH(F21,staging!$A$2:$A$5,0)),(2020+INDEX(staging!$B$2:$B$5,MATCH(F21,staging!$A$2:$A$5,0))-1)&"-01-01","")) -> 2020-08-01 | J21: FALSE | K21: MFN 0% → tiết kiệm = 0 | L21: CN/TARIC — cần tra | M21: C | P21: 2026-01-01 | Q21: 2026-12-31

Sheet staging
A1: category | B1: số đợt cắt giảm | C1: ý nghĩa | E1: năm chỉ số 2026
A2: B3 | B2: 4 | C2: 4 đợt bằng nhau từ ngày hiệu lực → 0% từ 1/1/2023 | E2: =2026-2020+1 -> 7
A3: B5 | B3: 6 | C3: 6 đợt → 0% từ 1/1/2025
A4: B7 | B4: 8 | C4: 8 đợt → 0% từ 1/1/2027
A5: A | B5: 0 | C5: Xóa bỏ ngay 1/8/2020
A7: Nguồn: EVFTA Phụ lục 2-A, đoạn định nghĩa nhóm lộ trình (data.consilium.europa.eu ST-6051-2019-ADD-1). Năm 1 = 2020.

Sheet psr_rules
A1: hs_code | B1: rule_type (WO/CTH/CTH_EXCEPT/MaxNOM/PROCESS) | C1: threshold_pct | D1: rule_text_vi | E1: requires_expert | F1: tolerance | G1: confidence | H1: source | I1: reviewed_by | J1: reviewed_at
A2: 0306.17 | B2: WO | D2: Toàn bộ nguyên liệu thuộc Chương 3 phải có xuất xứ thuần túy (tôm nuôi/đánh bắt tại VN hoặc EU). | E2: FALSE | F2: Không (WO) | G2: B | H2: EVFTA Nghị định thư 1, Phụ lục II (nhóm 0306); TT 11/2020/TT-BCT (hợp nhất 25/VBHN-BCT), phụ lục quy tắc cụ thể mặt hàng
A3: 1605.21 | B3: WO | D3: Toàn bộ nguyên liệu thuộc Chương 3 sử dụng phải có xuất xứ thuần túy. Tôm nhập từ nước thứ ba → không đạt. | E3: FALSE | F3: Không | G3: B | H3: EVFTA Nghị định thư 1, Phụ lục II (nhóm 1605); TT 11/2020/TT-BCT (hợp nhất 25/VBHN-BCT), phụ lục quy tắc cụ thể mặt hàng
A4: 1605.29 | B4: WO | D4: Như 1605.21 | E4: FALSE | F4: Không | G4: B | H4: EVFTA Nghị định thư 1, Phụ lục II (nhóm 1605); TT 11/2020/TT-BCT (hợp nhất 25/VBHN-BCT), phụ lục quy tắc cụ thể mặt hàng
A5: 0304.62 | B5: WO | D5: Toàn bộ nguyên liệu Chương 3 thuần túy. | E5: FALSE | F5: Không | G5: B | H5: EVFTA Nghị định thư 1, Phụ lục II (nhóm 0304); TT 11/2020/TT-BCT (hợp nhất 25/VBHN-BCT), phụ lục quy tắc cụ thể mặt hàng
A6: 0304.87 | B6: WO | D6: Như trên; cá đánh bắt ngoài lãnh hải cần điều kiện tàu (đăng ký, treo cờ, sở hữu) — NĐT1 Điều 4. | E6: TRUE nếu đánh bắt xa bờ | F6: Không | G6: B | H6: EVFTA Nghị định thư 1, Phụ lục II (nhóm 0304); TT 11/2020/TT-BCT (hợp nhất 25/VBHN-BCT), phụ lục quy tắc cụ thể mặt hàng
A7: 1604.14 | B7: WO | D7: Nguyên liệu Chương 3 thuần túy; điều kiện tàu như trên. | E7: TRUE (điều kiện tàu + TRQ) | F7: Không | G7: B | H7: EVFTA Nghị định thư 1, Phụ lục II (nhóm 1604); TT 11/2020/TT-BCT (hợp nhất 25/VBHN-BCT), phụ lục quy tắc cụ thể mặt hàng
A8: 0307.43 | B8: WO | D8: Toàn bộ nguyên liệu Chương 3 thuần túy. | E8: FALSE | F8: Không | G8: B | H8: EVFTA Nghị định thư 1, Phụ lục II (nhóm 0307); TT 11/2020/TT-BCT (hợp nhất 25/VBHN-BCT), phụ lục quy tắc cụ thể mặt hàng
A9: 0901.11 | B9: WO | D9: Sản phẩm nông nghiệp thu hoạch tại VN. | E9: FALSE | F9: Không | G9: C | H9: EVFTA Nghị định thư 1, Phụ lục II (nhóm 0901); TT 11/2020/TT-BCT (hợp nhất 25/VBHN-BCT), phụ lục quy tắc cụ thể mặt hàng
A10: 0901.21 | B10: CẦN TRA | D10: Chưa xác định quy tắc cho cà phê rang (WO nguyên liệu Ch.9 hay CTH). Không cho công cụ kết luận đến khi tra nguyên văn Phụ lục II. | E10: TRUE | F10: — | G10: C | H10: EVFTA Nghị định thư 1, Phụ lục II (nhóm 0901); TT 11/2020/TT-BCT (hợp nhất 25/VBHN-BCT), phụ lục quy tắc cụ thể mặt hàng
A11: 2101.11 | B11: CẦN TRA | D11: Chưa xác định (thường là CTH có điều kiện). Tra nguyên văn. | E11: TRUE | F11: — | G11: C | H11: EVFTA Nghị định thư 1, Phụ lục II (nhóm 2101); TT 11/2020/TT-BCT (hợp nhất 25/VBHN-BCT), phụ lục quy tắc cụ thể mặt hàng
A12: 0904.11 | B12: WO | D12: Hạt tiêu trồng và thu hoạch tại VN. Tiêu nhập khẩu rồi phân loại/đóng gói lại = gia công đơn giản, không đạt. | E12: FALSE | F12: Không | G12: C | H12: EVFTA Nghị định thư 1, Phụ lục II (nhóm 0904); TT 11/2020/TT-BCT (hợp nhất 25/VBHN-BCT), phụ lục quy tắc cụ thể mặt hàng
A13: 0801.32 | B13: WO | D13: Điều thô nhập từ châu Phi rồi bóc vỏ tại VN: cần tra quy tắc Ch.8 có yêu cầu nguyên liệu Ch.8 thuần túy không — rủi ro cao, ngành phụ thuộc điều thô nhập khẩu. | E13: TRUE | F13: — | G13: C | H13: EVFTA Nghị định thư 1, Phụ lục II (nhóm 0801); TT 11/2020/TT-BCT (hợp nhất 25/VBHN-BCT), phụ lục quy tắc cụ thể mặt hàng
... A21: 9403.60 | B21: CẦN TRA | D21: Có thể là CTH hoặc MaxNOM — tra nguyên văn trước khi cho tính %. | E21: TRUE | F21: — | G21: C | H21: EVFTA Nghị định thư 1, Phụ lục II (nhóm 9403); TT 11/2020/TT-BCT (hợp nhất 25/VBHN-BCT), phụ lục quy tắc cụ thể mặt hàng

Sheet c4_test_cases
A1: id | B1: hs_code | C1: tình huống | D1: dữ liệu nhập | E1: kết quả kỳ vọng của công cụ | F1: lý giải / điểm người duyệt xác nhận | G1: reviewed_by
A2: TC01 | B2: 0306.17 | C2: Tôm thẻ nuôi tại Cà Mau, sơ chế đông lạnh tại VN; bao bì nhập TQ | D2: Giá xuất xưởng 10.000 USD; nguyên liệu Ch.3: 100% VN | E2: Đạt | F2: WO đạt; bao bì bán lẻ không xét khi xác định xuất xứ nếu phân loại cùng hàng (xác nhận điều khoản)
A3: TC02 | B3: 0306.17 | C3: Tôm nguyên liệu nhập từ Ấn Độ, bóc vỏ và cấp đông tại VN | D3: Nguyên liệu Ch.3: 100% Ấn Độ | E3: Không đạt | F3: Nguyên liệu Ch.3 không thuần túy
A4: TC03 | B4: 1605.21 | C4: Tôm hấp tẩm bột, tôm nhập Ecuador 60%, tôm VN 40% | D4: 60% nguyên liệu Ch.3 không xuất xứ | E4: Không đạt | F4: WO không áp dụng dung sai cho nguyên liệu chính — xác nhận
A5: TC04 | B5: 1604.14 | C5: Cá ngừ đóng hộp, cá do tàu cờ VN đánh bắt ngoài vùng đặc quyền kinh tế | D5: Chưa có dữ liệu điều kiện tàu | E5: Chưa kết luận | F5: Phụ thuộc điều kiện tàu NĐT1 Điều 4; kèm cảnh báo hạn ngạch
A6: TC05 | B6: 0901.11 | C6: Cà phê nhân Đắk Lắk | D6: 100% VN | E6: Đạt | F6: WO; nhưng tiết kiệm thuế = 0 (MFN 0%)
A7: TC06 | B7: 0901.21 | C7: Cà phê rang tại VN từ hạt Brazil | D7: 100% nguyên liệu Ch.9 không xuất xứ | E7: Chưa kết luận | F7: PSR chưa tra (requires_expert = TRUE)
A8: TC07 | B8: 6109.10 | C8: Áo phông dệt kim tại VN từ sợi TQ, cắt may tại VN | D8: Sợi 100% TQ | E8: Chưa kết luận | F8: Quy tắc công đoạn → công cụ không tự kết luận; theo luật dự kiến đạt
A9: TC08 | B9: 6203.42 | C9: Quần dệt thoi, vải nhập TQ, cắt may tại VN | D9: Vải 100% TQ | E9: Chưa kết luận | F9: Công cụ không kết luận; theo luật dự kiến không đạt
A10: TC09 | B10: 6403.99 | C10: Giày da, đế và da nhập TQ (nhóm 4107, 6406 riêng lẻ), lắp ráp mũ vào đế tại VN | D10: Không dùng bộ mũ giày đã gắn đế | E10: Đạt | F10: CTH_EXCEPT: câu hỏi 'có dùng mũ giày đã gắn đế trong nhập khẩu?' = Không
A11: TC10 | B11: 6404.11 | C11: Giày thể thao, nhập bộ mũ giày đã gắn đế trong từ TQ, chỉ gắn đế ngoài tại VN | D11: Dùng hàng 6406 bị loại trừ | E11: Không đạt | F11: CTH_EXCEPT vi phạm

Sheet eur1_fields
A1: ô | B1: tên ô (VI) | C1: tên ô (EN) | D1: nguồn dữ liệu evfta.eu | E1: bắt buộc | F1: quy tắc / cảnh báo
A2: 1 | B2: Người xuất khẩu (tên, địa chỉ, nước) | C2: Exporter | D2: companies.legal_name + address + country | E2: Bắt buộc
A3: 2 | B3: Giấy chứng nhận dùng trong thương mại ưu đãi giữa … và … | C3: Certificate used in preferential trade between | D3: Cố định: VIET NAM and THE EUROPEAN UNION | E3: Bắt buộc | F3: Người duyệt xác nhận cách ghi theo mẫu TT 11/2020
A4: 3 | B4: Người nhận hàng (không bắt buộc) | C4: Consignee | D4: rfq/buyer company hoặc nhập tay | E4: Tùy chọn
A5: 4 | B5: Nước/nhóm nước/lãnh thổ xuất xứ | C5: Country of origin | D5: compliance_checks.origin_country (Viet Nam) | E5: Bắt buộc | F5: Chỉ điền khi C4 = Đạt
A6: 5 | B6: Nước nhập khẩu | C6: Country of destination | D6: compliance_checks.destination_country | E6: Bắt buộc
A7: 6 | B7: Chi tiết vận tải (không bắt buộc) | C7: Transport details | D7: Nhập tay | E7: Tùy chọn
A8: 7 | B8: Ghi chú | C8: Remarks | D8: Để trống; hệ thống không tự ghi 'ISSUED RETROSPECTIVELY'/'DUPLICATE' | E8: Tùy chọn | F8: Chỉ cơ quan cấp mới ghi các cụm này
A9: 8 | B9: Số thứ tự; ký hiệu, số lượng, loại kiện; mô tả hàng | C9: Item number; marks and numbers; description of goods | D9: products.name + hs_code + quantity + packages | E9: Bắt buộc | F9: Gạch chéo phần trống sau mô tả
A10: 9 | B10: Trọng lượng cả bì hoặc đơn vị đo khác | C10: Gross mass or other measure | D10: Nhập tay từ hóa đơn/phiếu đóng gói | E10: Bắt buộc
A11: 10 | B11: Hóa đơn (không bắt buộc) | C11: Invoices | D11: invoice_no + date | E11: Tùy chọn | F11: Hóa đơn bên thứ ba: ghi chú theo TT 11/2020
A12: 11 | B12: Xác nhận của cơ quan cấp | C12: Customs or competent authority endorsement | D12: LUÔN ĐỂ TRỐNG | E12: Không điền | F12: Hệ thống không được điền — ranh giới pháp lý
A13: 12 | B13: Khai báo của người xuất khẩu (nơi, ngày, chữ ký) | C13: Declaration by the exporter | D13: Nơi + ngày; chữ ký để trống | E13: Bắt buộc (ký tay/số bởi DN)
A15: Ghi chú Q8 | B15: Bố cục chuẩn EUR.1 (12 ô). File mẫu chính thức lấy từ phụ lục mẫu C/O EUR.1 của TT 11/2020/TT-BCT (bản hợp nhất) và NĐT1 EVFTA — người duyệt tải bản gốc để dev dựng layout PDF. Watermark 'DRAFT — for review before submission to issuing authority' mọi trang; ghi rõ cơ quan cấp: tổ chức được Bộ Công Thương ủy quyền.

Sheet corpus_manifest
A1: doc_id | B1: title | C1: source | D1: phạm vi dùng | E1: valid_from | F1: vai trò / ghi chú | G1: đã tải về | H1: reviewed_by
A2: DOC01 | B2: Hiệp định EVFTA — Nghị định thư 1 (Quy tắc xuất xứ và hợp tác hành chính) | C2: EUR-Lex, OJ L 186, 12/6/2020 (bản EN); bản VI: Bộ Công Thương | D2: Toàn văn + Phụ lục II (PSR), mẫu EUR.1, mẫu khai báo xuất xứ | E2: 2020-08-01 | F2: Nguồn chính — ưu tiên 1
A3: DOC02 | B3: EVFTA Phụ lục 2-A + Biểu cam kết của EU (2-A-1) | C3: data.consilium.europa.eu ST-6051-2019-ADD-1 | D3: Định nghĩa nhóm lộ trình, hạn ngạch (gạo, cá ngừ, surimi…) | E3: 2020-08-01 | F3: Nguồn chính
A4: DOC03 | B4: Thông tư 11/2020/TT-BCT, hợp nhất 25/VBHN-BCT (gồm sửa đổi TT 41/2022/TT-BCT) | C4: thuvienphapluat.vn / vbpl.vn | D4: Quy tắc xuất xứ tại VN, thủ tục cấp C/O, 8 phụ lục | E4: 2023-02-20 (bản hợp nhất) | F4: Nguồn chính — dùng bản hợp nhất, không dùng bản gốc
A5: DOC04 | B5: Nghị định 103/2020/NĐ-CP (chứng nhận gạo thơm xuất khẩu sang EU) | C5: vbpl.vn | D5: Điều kiện hạn ngạch gạo thơm | E5: 2020 | F5: Cần kiểm còn hiệu lực
A6: DOC05 | B6: Biểu thuế chung EU (Danh mục CN) năm 2026 + TARIC | C6: EUR-Lex (quy định thực thi CN hằng năm); ec.europa.eu/taxation_customs TARIC | D6: Mức MFN 2026 | E6: 2026-01-01 | F6: Số hiệu quy định CN 2026 cần tra
A7: DOC06 | B7: Hướng dẫn quy tắc xuất xứ EVFTA của Ủy ban châu Âu | C7: EC — DG TAXUD / Access2Markets | D7: Giải thích thực tế phía EU | E7: — | F7: Lớp tham khảo, không phải nguồn chính
A8: DOC07 | B8: Tóm tắt Nghị định thư 1 EVFTA — Trung tâm WTO (VCCI) | C8: wtocenter.vn/file/18298 | D8: Dùng cho FAQ tiếng Việt | E8: — | F8: Lớp tham khảo
A9: DOC08 | B9: Tóm tắt Chương 2 EVFTA (thuế quan) — Trung tâm WTO | C9: wtocenter.vn/file/18282 | D9: FAQ thuế | E9: — | F9: Lớp tham khảo
A10: DOC09 | B10: Cẩm nang xuất khẩu thủy sản vào EU — Bộ Công Thương (2024) | C10: goglobal.moit.gov.vn | D10: Lộ trình thuế thủy sản | E10: 2024 | F10: Lớp tham khảo
A11: DOC10 | B11: Văn bản hiện hành về tự chứng nhận xuất xứ / nhà xuất khẩu đủ điều kiện (phía VN) | C11: Cần tìm | D11: Trả lời câu hỏi lô ≤ 6.000 EUR | E11: — | F11: CHƯA XÁC ĐỊNH — xem cau_hoi_mo #1

Sheet cau_hoi_mo
A1: # | B1: câu hỏi | C1: hiện trạng | D1: ảnh hưởng | E1: ưu tiên | F1: kết luận người duyệt
A2: 1 | B2: Tự chứng nhận lô ≤ 6.000 EUR (chiều VN → EU) | C2: Backlog ghi là được. Deloitte (2020): phía VN chưa triển khai tự chứng nhận, chỉ dùng EUR.1. Cần văn bản hiện hành. | D2: C6, C5, copilot Q20 | E2: Cao
A3: 2 | B3: Nhóm lộ trình cho 2101.11, 6109.10, 6203.42, 6403.99, 6404.11 | C3: Để trống, không đoán. Tra Biểu 2-A-1. | D3: C1, C2 | E3: Cao
A4: 3 | B4: Quy tắc làm tròn mức thuế trung gian (B7 năm 2026) | C4: Ảnh hưởng số tiền hiển thị. | D4: C2 | E4: Trung bình
A5: 4 | B5: PSR nguyên văn cho 0901.21, 2101.11, 1905.90, 9403.60, 0801.32 | C5: Hiện để requires_expert = TRUE. | D5: C4 | E5: Cao
A6: 5 | B6: Điều 0801.32: điều thô nhập khẩu bóc vỏ tại VN có đạt không | C6: Ngành điều VN phụ thuộc lớn vào điều thô nhập khẩu — nếu không đạt, đây là thông điệp quan trọng cho người dùng. | D6: C4, copilot | E6: Cao
A7: 6 | B7: Cộng gộp vải Nhật Bản/Canada cho Ch.61–62 | C7: Nguồn thứ cấp mâu thuẫn (chỉ Hàn Quốc vs Hàn + Nhật + Canada). Cần điều kiện áp dụng thực tế. | D7: C4, copilot Q12 | E7: Trung bình
A8: 7 | B8: Danh sách giống gạo thơm trong hạn ngạch; ST25 | C8: Xác nhận ST25 không thuộc danh sách. | D8: C2, copilot Q8 | E8: Cao
A9: 8 | B9: Mẫu EUR.1 chính thức (file) theo TT 11/2020 | C9: Tải bản gốc cho dev dựng layout. | D9: C5 (Q8) | E9: Cao
A10: 9 | B10: Mức MFN 2026 cho mọi dòng confidence C | C10: Đối chiếu TARIC từng dòng 8 số. | D10: C1 | E10: Cao

Sheet copilot_50
A1: id | B1: lang | C1: category | D1: question | E1: expected_answer | F1: must_cite | G1: expected_confidence | H1: reviewer_note | I1: đúng/sai (người duyệt) | J1: sửa đáp án
A2: Q01 | B2: vi | C2: khung pháp lý | D2: EVFTA có hiệu lực từ ngày nào? | E2: Ngày 1/8/2020. | F2: EVFTA, TT 11/2020/TT-BCT | G2: high
A3: Q02 | B3: vi | C3: khung pháp lý | D3: Quy tắc xuất xứ EVFTA ở Việt Nam được quy định tại văn bản nào? | E3: TT 11/2020/TT-BCT, được sửa đổi bởi TT 41/2022/TT-BCT (hiệu lực 20/2/2023); dùng văn bản hợp nhất 25/VBHN-BCT. | F3: DOC03 | G3: high
A4: Q03 | B4: vi | C4: thủ tục | D4: Ai cấp C/O mẫu EUR.1 cho hàng đi EU? | E4: Các cơ quan, tổ chức cấp C/O ưu đãi được Bộ Công Thương ủy quyền. Nền tảng chỉ tạo bản nháp. | F4: DOC03 | G4: high
A5: Q04 | B5: vi | C5: thuế | D5: Tôm đông lạnh HS 0306.17 xuất sang EU chịu thuế EVFTA bao nhiêu? | E5: 0% từ ngày hiệu lực đối với các dòng 0306 17 91–99 (MFN 12%). Dòng 0306 17 10 cần tra riêng. | F5: DOC02 | G5: high
A6: Q05 | B6: vi | C6: thuế | D6: Tôm chế biến 1605.21 năm 2026 chịu thuế bao nhiêu? | E6: Thuế cơ sở 20%. Nếu thuộc nhóm B7: năm 2026 còn 1/8 mức cơ sở (khoảng 2,5%), về 0% từ 1/1/2027. Cần xác nhận nhóm lộ trình. | F6: DOC02 | G6: medium | H6: Phụ thuộc cau_hoi_mo #2/#3
A7: Q06 | B7: vi | C7: hạn ngạch | D7: Cá ngừ đóng hộp có được thuế 0% không? | E7: Có, trong hạn ngạch 11.500 tấn/năm; ngoài hạn ngạch áp thuế MFN. Nguyên liệu cá phải có xuất xứ thuần túy. | F7: DOC02, DOC01 | G7: high
A8: Q07 | B8: vi | C8: hạn ngạch | D8: Hạn ngạch surimi theo EVFTA là bao nhiêu? | E8: 500 tấn/năm. | F8: DOC02 | G8: high
A9: Q08 | B9: vi | C9: hạn ngạch | D9: Gạo ST25 có được hưởng hạn ngạch gạo thơm 0% không? | E9: Hạn ngạch gạo thơm chỉ áp dụng cho các giống liệt kê trong cam kết; theo ghi nhận hiện có ST25 không thuộc danh sách, nên không được khẳng định hưởng 0%. Đề nghị chuyển chuyên gia. | F9: DOC02, DOC04 | G9: medium | H9: Phải trả lời thận trọng + đề xuất chuyển người thật
A10: Q09 | B10: vi | C10: hạn ngạch | D10: Tổng hạn ngạch gạo EU dành cho Việt Nam mỗi năm? | E10: 80.000 tấn/năm (gồm gạo xay xát, gạo lứt, gạo thơm). | F10: DOC02 | G10: high | H10: Tách chi tiết theo loại khi tra 2-A-1
A11: Q10 | B11: vi | C11: xuất xứ | D11: Hàng dệt may cần điều kiện gì để có xuất xứ EVFTA? | E11: Quy tắc 'từ vải trở đi': vải phải dệt tại VN/EU và cắt may tại VN; Ch.61–62 được cộng gộp vải có xuất xứ Hàn Quốc. | F11: DOC01 Phụ lục II | G11: high
A12: Q11 | B12: vi | C12: xuất xứ | D12: Tôi may áo sơ mi từ vải nhập Trung Quốc, xuất sang EU có hưởng EVFTA không? | E12: Không, vì vải không có xuất xứ VN/EU hay vải được cộng gộp. | F12: DOC01 Phụ lục II | G12: high
A13: Q12 | B13: vi | C13: cộng gộp | D13: Vải nhập từ Nhật Bản có được cộng gộp cho hàng may mặc không? | E13: Cộng gộp vải Hàn Quốc đã quy định rõ; mở rộng sang nước khác phụ thuộc điều kiện trong NĐT1. Chưa đủ căn cứ khẳng định — chuyển chuyên gia. | F13: DOC01 | G13: low | H13: Kiểm tra hành vi không khẳng định bừa
A14: Q13 | B14: vi | C14: xuất xứ | D14: Quy tắc xuất xứ cho giày dép là gì? | E14: Được sản xuất từ nguyên liệu thuộc bất kỳ nhóm nào, trừ bộ mũ giày đã gắn đế trong hoặc bộ phận đế khác thuộc nhóm 6406. | F14: DOC01 Phụ lục II Ch.64 | G14: medium
A15: Q14 | B15: vi | C15: xuất xứ | D15: Tôi dùng cá hồi nhập từ Na Uy để chế biến tại VN, có được ưu đãi EVFTA không? | E15: Không, sản phẩm chế biến Ch.16 yêu cầu nguyên liệu Ch.3 có xuất xứ thuần túy; Na Uy không thuộc EU nên không cộng gộp được. | F15: DOC01 Phụ lục II | G15: medium
A16: Q15 | B16: vi | C16: xuất xứ | D16: Cá do tàu nước ngoài đánh bắt trong vùng biển Việt Nam có xuất xứ Việt Nam không? | E16: Phụ thuộc điều kiện về tàu (đăng ký, treo cờ, sở hữu) theo NĐT1; không đủ thông tin để kết luận. | F16: DOC01 Điều 4 | G16: medium
A17: Q16 | B17: vi | C17: xuất xứ | D17: Mức dung sai nguyên liệu không xuất xứ chung là bao nhiêu? | E17: 10% giá xuất xưởng với hàng ngoài dệt may; dệt may theo ghi chú riêng tại Phụ lục II. Không áp dụng để vượt ngưỡng tỷ lệ tối đa của quy tắc cụ thể. | F17: DOC01 | G17: medium | H17: Xác nhận số điều
A18: Q17 | B18: vi | C18: thủ tục | D18: C/O EUR.1 có hiệu lực bao lâu? | E18: 12 tháng kể từ ngày cấp. | F18: DOC01, DOC03 | G18: high
A19: Q18 | B19: vi | C19: thủ tục | D19: Có thể xin cấp EUR.1 sau khi hàng đã xuất không? | E19: Có trong một số trường hợp (không cấp được lúc xuất do lỗi, sơ suất hoặc hoàn cảnh đặc biệt); C/O ghi 'ISSUED RETROSPECTIVELY'. | F19: DOC01, DOC03 | G19: medium
A20: Q19 | B20: vi | C20: thủ tục | D20: Mất bản gốc EUR.1 thì làm thế nào? | E20: Đề nghị cơ quan cấp phát hành bản sao chứng thực ghi 'DUPLICATE' dựa trên hồ sơ lưu. | F20: DOC01, DOC03 | G20: medium
A21: Q20 | B21: vi | C21: tự chứng nhận | D21: Lô hàng dưới 6.000 EUR có tự chứng nhận xuất xứ được không? | E21: Hiệp định cho phép với lô ≤ 6.000 EUR, nhưng việc áp dụng phía Việt Nam phụ thuộc quy định trong nước hiện hành — chưa đủ căn cứ, chuyển chuyên gia. | F21: DOC01, DOC10 | G21: low | H21: Phụ thuộc cau_hoi_mo #1
A22: Q21 | B22: vi | C22: tự chứng nhận | D22: Làm thế nào để trở thành nhà xuất khẩu đủ điều kiện tự chứng nhận? | E22: Chưa có căn cứ trong kho tài liệu về quy trình hiện hành phía VN — chuyển chuyên gia. | F22: DOC10 | G22: low
A23: Q22 | B23: vi | C23: vận chuyển | D23: Hàng quá cảnh qua Singapore có mất ưu đãi EVFTA không? | E23: Không, nếu hàng không bị thay đổi, chỉ bốc dỡ/lưu kho và chịu giám sát hải quan (điều khoản không thay đổi); cần chứng từ chứng minh khi được yêu cầu. | F23: DOC01 | G23: medium
A24: Q23 | B24: vi | C24: vận chuyển | D24: Tôi chia nhỏ lô hàng tại kho ở Singapore rồi mới gửi sang EU, có được không? | E24: Có thể được nếu hàng vẫn chịu giám sát hải quan và không bị thay đổi; tình huống cụ thể nên chuyển chuyên gia. | F24: DOC01 | G24: medium
A25: Q24 | B25: vi | C25: thủ tục | D25: Hóa đơn do công ty ở Hồng Kông phát hành có dùng với EUR.1 được không? | E25: Được, EVFTA chấp nhận hóa đơn bên thứ ba; người bán có thể ở nước ngoài khu vực EVFTA. | F25: DOC03 Điều 3 | G25: high
A26: Q25 | B26: vi | C26: khái niệm | D26: Giá xuất xưởng là gì? | E26: Giá trả cho nhà sản xuất thực hiện công đoạn cuối, gồm trị giá nguyên liệu và chi phí sản xuất, trừ thuế nội địa được hoàn khi xuất khẩu. | F26: DOC03 Điều 3 | G26: high
A27: Q26 | B27: vi | C27: thuế | D27: Cà phê nhân xuất sang EU tiết kiệm được bao nhiêu thuế nhờ EVFTA? | E27: Không có chênh lệch: thuế MFN cà phê nhân đã là 0%. | F27: DOC05 | G27: medium | H27: Xác nhận MFN
A28: Q27 | B28: vi | C28: thuế | D28: Thuế cà phê rang sang EU theo EVFTA? | E28: 0% từ ngày hiệu lực; MFN 7,5%. | F28: DOC02, DOC05 | G28: medium | H28: Xác nhận MFN + nhóm A
A29: Q28 | B29: vi | C29: thuế | D29: Hạt tiêu xuất EU có được giảm thuế nhờ EVFTA không? | E29: Thuế MFN đã là 0%, nên EVFTA không tạo chênh lệch thuế. | F29: DOC05 | G29: medium
A30: Q29 | B30: vi | C30: xuất xứ | D30: Điều thô nhập khẩu từ Bờ Biển Ngà, bóc vỏ tại Việt Nam có xuất xứ Việt Nam không? | E30: Phụ thuộc quy tắc cụ thể Ch.08 — chưa đủ căn cứ, chuyển chuyên gia. | F30: DOC01 Phụ lục II | G30: low | H30: cau_hoi_mo #5
A31: Q30 | B31: vi | C31: xuất xứ | D31: Chỉ đóng gói lại và dán nhãn tại Việt Nam có tạo xuất xứ không? | E31: Không, đây là công đoạn gia công chế biến đơn giản, không đủ tạo xuất xứ. | F31: DOC01 | G31: high
A32: Q31 | B32: vi | C32: cộng gộp | D32: Có được dùng nguyên liệu từ Thái Lan và vẫn tính là có xuất xứ không? | E32: NĐT1 cho phép cộng gộp nguyên liệu ASEAN với điều kiện (nước ASEAN có FTA với EU, có thỏa thuận hợp tác hành chính, một số mặt hàng bị loại trừ). Cần kiểm tra điều kiện cụ thể. | F32: DOC01 | G32: low
A33: Q32 | B33: vi | C33: thuế | D33: Thuế giày thể thao 6404.11 sang EU năm 2026? | E33: Thuế cơ sở MFN khoảng 16,9%; mức EVFTA năm 2026 phụ thuộc nhóm lộ trình — chưa tra được, không đưa ra con số. | F33: DOC02, DOC05 | G33: low | H33: Kiểm tra hành vi không đoán
A34: Q33 | B34: vi | C34: chứng từ | D34: Nước xuất xứ ghi ở ô nào trên EUR.1? | E34: Ô số 4. | F34: DOC01 mẫu EUR.1 | G34: high
A35: Q34 | B35: vi | C35: chứng từ | D35: Ô 11 của EUR.1 do ai điền? | E35: Cơ quan/tổ chức cấp C/O xác nhận; doanh nghiệp không tự điền. | F35: DOC01 mẫu EUR.1 | G35: high
A36: Q35 | B36: vi | C36: xuất xứ | D36: Hàng có xuất xứ thuần túy gồm những loại nào? | E36: Như: khoáng sản khai thác, cây trồng thu hoạch, động vật sinh ra và nuôi, sản phẩm đánh bắt trong lãnh thổ, sản phẩm từ tàu đáp ứng điều kiện, phế liệu từ sản xuất tại lãnh thổ… | F36: DOC01 Điều 4 | G36: high
A37: Q36 | B37: vi | C37: thuế | D37: Thuế gạo tính theo tấn thì tính tiết kiệm như thế nào? | E37: Thuế MFN gạo là thuế tuyệt đối (EUR/tấn); cần khối lượng lô hàng và điều kiện hạn ngạch. Công cụ trả 'cần kiểm thêm'. | F37: DOC02, DOC05 | G37: medium
A38: Q37 | B38: vi | C38: ngoài phạm vi | D38: Thuế đối ứng của Mỹ với tôm Việt Nam hiện là bao nhiêu? | E38: Ngoài phạm vi (không thuộc EVFTA). | G38: out_of_scope
A39: Q38 | B39: vi | C39: ngoài phạm vi | D39: Hạn áp dụng EUDR cho cà phê là khi nào? | E39: Ngoài phạm vi kho tài liệu hiện tại — gợi ý liên hệ chuyên gia. | G39: out_of_scope
A40: Q39 | B40: vi | C40: ngoài phạm vi | D40: Thủ tục thành lập công ty con tại Đức? | E40: Ngoài phạm vi. | G40: out_of_scope
...
