Workbook

Sheet Đọc trước
A1: evfta.eu — Backlog MVP xây mới trên FastAPI
A2: Mục đích | B2: Backlog xây mới evfta.eu MVP theo spec evfta.eu MVP Build Specification. Stack: FastAPI (Python), Next.js, PostgreSQL.
A3: Căn cứ | B3: Spec EVFTA (P0/P1/P2, §4 mô hình dữ liệu, §5 chức năng, §9 lịch 12 tuần); backlog VYBE Trade 29/9/2026 (đính chính nghiệp vụ, lỗi đã gặp); tài liệu 'evfta.eu MVP — Chức năng yêu cầu và kế hoạch thực thi'.
A4: Khác với backlog VYBE | B4: VYBE là sửa trên nền Blazor + XAF. evfta.eu là xây mới, nên không có cột 'Hiện trạng web' hay 'Tận dụng code'. Cột 'Tham chiếu VYBE' giữ mã cũ để đối chiếu và ghi bài học. Admin XAF không còn: I4, I1, I5 phải tự làm trên Next.js.
A5: Cách đọc | B5: Sheet 'Backlog' xếp theo giai đoạn thực thi. Cột 'Xong khi' lấy từ tiêu chí nghiệm thu của spec. Công sức là ước lượng ngày-người cho xây mới; tech lead chỉnh sau tuần 1.
A6: Giai đoạn | B6: GĐ1 29/9–12/10 nền tảng, tài khoản, hồ sơ · GĐ2 13/10–26/10 máy tính thuế và xuất xứ · GĐ3 27/10–9/11 chứng từ và xác minh · GĐ4 10/11–23/11 trợ lý AI · GĐ5 24/11–7/12 danh bạ và kết nối · GĐ6 8/12–21/12 dashboard, gia cố, pilot.
A7: Luồng song song | B7: VYBE (Duy Tân) chạy tới launch 10/10 và SIAL 17–21/10, rồi đóng băng tính năng. Dữ liệu VYBE chuyển sang evfta.eu ở tuần 12 (J6).
A8: Điểm nghẽn | B8: Người duyệt luật TM. Nhu cầu dồn vào GĐ1–GĐ2 (C0, D0, C1, C4): khoảng 11.5 ngày trong 4 tuần, trong khi 30% thời gian chỉ có 6 ngày. Xem sheet 'Tổng hợp'.
A9: Đính chính spec | B9: EUR.1 cho EVFTA do Bộ Công Thương cấp, không phải VCCI. Lô ≤ 6.000 EUR được tự chứng nhận xuất xứ. Chứng từ xuất xứ hiệu lực 12 tháng. Nguồn: backlog VYBE; luật TM xác nhận trong tuần 1.
A10: Cảnh báo dữ liệu | B10: Gạo ST25 không thuộc 9 giống gạo thơm được hạn ngạch 0% (theo backlog VYBE). Máy tính thuế phải trả 'cần kiểm thêm', không được ra 0%.
A11: Cần chốt tuần 1 | B11: 1) Ai xây luồng B (2 BE Python, 2 FE Next.js). 2) Người duyệt luật TM và % thời gian. 3) Kỹ sư AI từ tuần 5. 4) Hosting vùng EU, cơ chế phiên đăng nhập (ADR).
A12: Trạng thái | B12: Cột 'Trạng thái' chọn từ danh sách: Chưa bắt đầu / Đang làm / Xong / Tắc. Cột 'Người phụ trách' để trống, PO điền khi giao việc.
A13: Ô nhập | B13: Chữ xanh dương ở sheet 'Tổng hợp' là giả định năng lực. Sửa trực tiếp, các số tổng tự tính lại.
A14: Nguyên tắc phạm vi | B14: Khi trễ: giữ P0, cắt P1 trước. Không làm P2. Yêu cầu P2 từ pilot trả lời 'đưa vào lộ trình seed'.

Sheet Tổng hợp
A1: Giả định năng lực (sửa ô chữ xanh)
A2: Chỉ tiêu | B2: Giá trị | C2: Ghi chú
A3: Số dev (BE + FE) | B3: 4 | C3: 2 BE Python + 2 FE Next.js; kỹ sư AI tính riêng
A4: Ngày làm việc mỗi giai đoạn | B4: 10 | C4: 2 tuần, trừ cuối tuần
A5: Hệ số tập trung | B5: 0.7 | C5: Trừ họp, sửa lỗi phát sinh, hỗ trợ VYBE
A6: % thời gian luật TM | B6: 0.3 | C6: Theo spec §10; nên tăng lên 0.5–0.6 ở GĐ1–GĐ2
A7: Dự phòng công sức | B7: 0.2 | C7: Ước lượng xây mới còn thô
A10: Theo giai đoạn
A11: Giai đoạn | B11: Số hạng mục | C11: Dev (ngày) | D11: Luật TM (ngày) | E11: Năng lực dev (ngày) | F11: Dư / thiếu dev | G11: Năng lực luật TM (ngày) | H11: Dư / thiếu luật TM
A12: GĐ1 · T1–2 · 29/9–12/10 | B12: =COUNTIFS(Backlog!$J$2:$J$58,A12) -> 13 | C12: =SUMIFS(Backlog!$H$2:$H$58,Backlog!$J$2:$J$58,A12) -> 24.5 | D12: =SUMIFS(Backlog!$I$2:$I$58,Backlog!$J$2:$J$58,A12) -> 6.5 | E12: =$B$3*$B$4*$B$5 -> 28 | F12: =E12-C12*(1+$B$7) -> -1.4 | G12: =$B$4*$B$6 -> 3 | H12: =G12-D12 -> -3.5
A13: GĐ2 · T3–4 · 13/10–26/10 | B13: =COUNTIFS(Backlog!$J$2:$J$58,A13) -> 5 | C13: =SUMIFS(Backlog!$H$2:$H$58,Backlog!$J$2:$J$58,A13) -> 11 | D13: =SUMIFS(Backlog!$I$2:$I$58,Backlog!$J$2:$J$58,A13) -> 5 | E13: =$B$3*$B$4*$B$5 -> 28 | F13: =E13-C13*(1+$B$7) -> 14.8 | G13: =$B$4*$B$6 -> 3 | H13: =G13-D13 -> -2
A14: GĐ3 · T5–6 · 27/10–9/11 | B14: =COUNTIFS(Backlog!$J$2:$J$58,A14) -> 8 | C14: =SUMIFS(Backlog!$H$2:$H$58,Backlog!$J$2:$J$58,A14) -> 17 | D14: =SUMIFS(Backlog!$I$2:$I$58,Backlog!$J$2:$J$58,A14) -> 1.5 | E14: =$B$3*$B$4*$B$5 -> 28 | F14: =E14-C14*(1+$B$7) -> 7.6 | G14: =$B$4*$B$6 -> 3 | H14: =G14-D14 -> 1.5
A15: GĐ4 · T7–8 · 10/11–23/11 | B15: =COUNTIFS(Backlog!$J$2:$J$58,A15) -> 4 | C15: =SUMIFS(Backlog!$H$2:$H$58,Backlog!$J$2:$J$58,A15) -> 12 | D15: =SUMIFS(Backlog!$I$2:$I$58,Backlog!$J$2:$J$58,A15) -> 3 | E15: =$B$3*$B$4*$B$5 -> 28 | F15: =E15-C15*(1+$B$7) -> 13.6 | G15: =$B$4*$B$6 -> 3 | H15: =G15-D15 -> 0
A16: GĐ5 · T9–10 · 24/11–7/12 | B16: =COUNTIFS(Backlog!$J$2:$J$58,A16) -> 11 | C16: =SUMIFS(Backlog!$H$2:$H$58,Backlog!$J$2:$J$58,A16) -> 19 | D16: =SUMIFS(Backlog!$I$2:$I$58,Backlog!$J$2:$J$58,A16) -> 0 | E16: =$B$3*$B$4*$B$5 -> 28 | F16: =E16-C16*(1+$B$7) -> 5.2 | G16: =$B$4*$B$6 -> 3 | H16: =G16-D16 -> 3
A17: GĐ6 · T11–12 · 8/12–21/12 | B17: =COUNTIFS(Backlog!$J$2:$J$58,A17) -> 8 | C17: =SUMIFS(Backlog!$H$2:$H$58,Backlog!$J$2:$J$58,A17) -> 14 | D17: =SUMIFS(Backlog!$I$2:$I$58,Backlog!$J$2:$J$58,A17) -> 0 | E17: =$B$3*$B$4*$B$5 -> 28 | F17: =E17-C17*(1+$B$7) -> 11.2 | G17: =$B$4*$B$6 -> 3 | H17: =G17-D17 -> 3
A18: Sau MVP | B18: =COUNTIFS(Backlog!$J$2:$J$58,A18) -> 1 | C18: =SUMIFS(Backlog!$H$2:$H$58,Backlog!$J$2:$J$58,A18) -> 0 | D18: =SUMIFS(Backlog!$I$2:$I$58,Backlog!$J$2:$J$58,A18) -> 0
A19: Không làm (P2) | B19: =COUNTIFS(Backlog!$J$2:$J$58,A19) -> 7 | C19: =SUMIFS(Backlog!$H$2:$H$58,Backlog!$J$2:$J$58,A19) -> 0 | D19: =SUMIFS(Backlog!$I$2:$I$58,Backlog!$J$2:$J$58,A19) -> 0
A20: Tổng | B20: =SUM(B12:B19) -> 57 | C20: =SUM(C12:C19) -> 97.5 | D20: =SUM(D12:D19) -> 16 | E20: =SUM(E12:E19) -> 168 | F20: =SUM(F12:F19) -> 51 | G20: =SUM(G12:G19) -> 18 | H20: =SUM(H12:H19) -> 2
A21: Dư / thiếu âm (chữ đỏ) = giai đoạn quá tải. Nhu cầu dev đã cộng dự phòng ở B7.
A23: Tổng thể
A24: Chỉ tiêu | B24: Giá trị | C24: Ghi chú
A25: Nhu cầu dev có dự phòng (ngày) | B25: =C20*(1+B7) -> 117 | C25: Tổng dev × (1 + dự phòng)
A26: Năng lực dev 6 giai đoạn (ngày) | B26: =B3*B4*6*B5 -> 168
A27: Dư / thiếu dev (ngày) | B27: =B26-B25 -> 51
A28: Kết luận dev | B28: =IF(B27<0,"Thiếu năng lực: cắt P1 hoặc thêm người","Đủ năng lực") -> Đủ năng lực
A29: Nhu cầu luật TM (ngày) | B29: =D20 -> 16
A30: Năng lực luật TM 12 tuần (ngày) | B30: =B4*6*B6 -> 18
A31: Kết luận luật TM | B31: =IF(COUNTIFS(H12:H17,"<0")>0,"Quá tải ở "&COUNTIFS(H12:H17,"<0")&" giai đoạn: tăng % thời gian GĐ1–GĐ2","Đủ năng lực") -> Quá tải ở 2 giai đoạn: tăng % thời gian GĐ1–GĐ2 | C31: Tổng có thể đủ nhưng dồn vào đầu dự án
A33: Theo ưu tiên
A34: Ưu tiên | B34: Số hạng mục | C34: Dev (ngày) | D34: Luật TM (ngày)
A35: P0 | B35: =COUNTIFS(Backlog!$C$2:$C$58,A35) -> 47 | C35: =SUMIFS(Backlog!$H$2:$H$58,Backlog!$C$2:$C$58,A35) -> 95 | D35: =SUMIFS(Backlog!$I$2:$I$58,Backlog!$C$2:$C$58,A35) -> 16
A36: P1 | B36: =COUNTIFS(Backlog!$C$2:$C$58,A36) -> 2 | C36: =SUMIFS(Backlog!$H$2:$H$58,Backlog!$C$2:$C$58,A36) -> 2.5 | D36: =SUMIFS(Backlog!$I$2:$I$58,Backlog!$C$2:$C$58,A36) -> 0
A37: P2 | B37: =COUNTIFS(Backlog!$C$2:$C$58,A37) -> 7 | C37: =SUMIFS(Backlog!$H$2:$H$58,Backlog!$C$2:$C$58,A37) -> 0 | D37: =SUMIFS(Backlog!$I$2:$I$58,Backlog!$C$2:$C$58,A37) -> 0
A38: — | B38: =COUNTIFS(Backlog!$C$2:$C$58,A38) -> 1 | C38: =SUMIFS(Backlog!$H$2:$H$58,Backlog!$C$2:$C$58,A38) -> 0 | D38: =SUMIFS(Backlog!$I$2:$I$58,Backlog!$C$2:$C$58,A38) -> 0
A40: Theo module
A41: Module | B41: Số hạng mục | C41: Dev (ngày) | D41: Luật TM (ngày)
A42: Nền tảng | B42: =COUNTIFS(Backlog!$D$2:$D$58,A42) -> 2 | C42: =SUMIFS(Backlog!$H$2:$H$58,Backlog!$D$2:$D$58,A42) -> 7 | D42: =SUMIFS(Backlog!$I$2:$I$58,Backlog!$D$2:$D$58,A42) -> 0
A43: Admin | B43: =COUNTIFS(Backlog!$D$2:$D$58,A43) -> 6 | C43: =SUMIFS(Backlog!$H$2:$H$58,Backlog!$D$2:$D$58,A43) -> 11 | D43: =SUMIFS(Backlog!$I$2:$I$58,Backlog!$D$2:$D$58,A43) -> 0
A44: Tài khoản | B44: =COUNTIFS(Backlog!$D$2:$D$58,A44) -> 3 | C44: =SUMIFS(Backlog!$H$2:$H$58,Backlog!$D$2:$D$58,A44) -> 7 | D44: =SUMIFS(Backlog!$I$2:$I$58,Backlog!$D$2:$D$58,A44) -> 0
A45: Hồ sơ | B45: =COUNTIFS(Backlog!$D$2:$D$58,A45) -> 5 | C45: =SUMIFS(Backlog!$H$2:$H$58,Backlog!$D$2:$D$58,A45) -> 9 | D45: =SUMIFS(Backlog!$I$2:$I$58,Backlog!$D$2:$D$58,A45) -> 0.5
...

Sheet Backlog
A1: ID | B1: Mục spec | C1: Ưu tiên | D1: Module | E1: Chức năng | F1: Việc cần làm (kỹ thuật) | G1: Xong khi | H1: Dev (ngày) | I1: Luật TM (ngày) | J1: Giai đoạn | K1: Tuần | L1: Vai trò | M1: Phụ thuộc | N1: Tham chiếu VYBE / bài học | O1: Trạng thái | P1: Người phụ trách
A2: J7 | B2: §8 | C2: P0 | D2: Nền tảng | E2: Repo, CI/CD, môi trường | F2: Monorepo backend/ + frontend/; uv, ruff, mypy strict, pytest; GitHub Actions chạy lint, test, build; môi trường dev/staging/prod vùng EU; Alembic migration đầu tiên; CLAUDE.md và spec trong docs/; ADR hosting và phiên đăng nhập. | G2: Merge vào main tự deploy staging; CI đỏ thì chặn merge; ADR hosting và phiên đăng nhập đã ký. | H2: 4 | I2: 0 | J2: GĐ1 · T1–2 · 29/9–12/10 | K2: T1 | L2: BE | M2: — | N2: Mới — VYBE chạy .NET/XAF, không tái sử dụng | O2: Chưa bắt đầu
A3: A0 | B3: §5.1 · §8 | C3: P0 | D3: Nền tảng | E3: Khung giao diện hai vai trò + bộ component | F3: Next.js App Router; layout riêng cho khách, nhà xuất khẩu, buyer, admin; bộ component cơ bản; client TypeScript sinh từ OpenAPI (npm run generate:api); i18n next-intl vi/en. | G3: Bốn khung layout chạy trên staging; client API sinh tự động, không viết tay kiểu dữ liệu. | H3: 3 | I3: 0 | J3: GĐ1 · T1–2 · 29/9–12/10 | K3: T1–2 | L3: FE | M3: J7 | N3: Mới — thay cho portal Blazor | O3: Chưa bắt đầu
A4: I6 | B4: §4.11 · §6 | C4: P0 | D4: Admin | E4: Nhật ký kiểm toán (AuditLog) | F4: Bảng audit_logs (actor, action, entity, before, after, at) append-only; ghi qua một service chung dùng cho mọi module; màn hình admin lọc theo đối tượng. | G4: Quyết định xác minh, câu trả lời AI, lần sinh chứng từ đều có người, lúc, trước, sau. | H4: 1.5 | I4: 0 | J4: GĐ1 · T1–2 · 29/9–12/10 | K4: T2 | L4: BE + FE | M4: J7 | N4: VYBE I6 — nhật ký bị ẩn khỏi menu admin | O4: Chưa bắt đầu
A5: A1 | B5: §5.1 · §4.1 · §6 | C5: P0 | D5: Tài khoản | E5: Đăng ký, đăng nhập, phiên, phân quyền | F5: Bảng users (email, phone, password_hash Argon2, role, preferred_language, consent_accepted_at, consent_version, last_login_at); /register đọc ?type=buyer|exporter; phiên cookie HTTP-only; mật khẩu ≥ 10 ký tự; khóa 15 phút sau 5 lần sai; phân quyền bằng dependency FastAPI trên mọi route. | G5: Lưu đủ trường; ?type=buyer chọn sẵn Buyer; mật khẩu rỗng bị chặn ở server (test đủ 4 vai trò); sai 5 lần bị khóa 15 phút. | H5: 3 | I5: 0 | J5: GĐ1 · T1–2 · 29/9–12/10 | K5: T1–2 | L5: BE + FE | M5: J7 | N5: VYBE A1, A2 — từng vào được admin bằng mật khẩu rỗng | O5: Chưa bắt đầu
A6: A2 | B6: §5.1 | C6: P0 | D6: Tài khoản | E6: Wizard tạo hồ sơ ngay sau đăng ký | F6: 3 bước: pháp lý → sản phẩm/mã HS → bằng chứng; lưu nháp từng bước; tài khoản chưa có công ty luôn được nhắc. | G6: Từ trang chủ tới hồ sơ nháp đã lưu dưới 3 phút trên điện thoại và máy tính (đo với 3 người). | H6: 2 | I6: 0 | J6: GĐ1 · T1–2 · 29/9–12/10 | K6: T2 | L6: FE | M6: A1, B1 | N6: VYBE A3 | O6: Chưa bắt đầu
A7: A3 | B7: §5.1 · §6 | C7: P0 | D7: Tài khoản | E7: Song ngữ Việt/Anh toàn hệ thống | F7: Mọi chuỗi giao diện qua next-intl; email và thông báo dùng mẫu song ngữ ở backend; nút đổi ngôn ngữ lưu preferred_language + cookie; bước CI báo chuỗi cứng. | G7: Không còn chuỗi cứng; đổi ngôn ngữ không mất dữ liệu đang nhập. | H7: 2 | I7: 0 | J7: GĐ1 · T1–2 · 29/9–12/10 | K7: T1–11 | L7: FE | M7: A0 | N7: VYBE A4 — portal chỉ có tiếng Anh | O7: Chưa bắt đầu
A8: B1 | B8: §5.2 · §4.2 | C8: P0 | D8: Hồ sơ | E8: Hồ sơ nhà xuất khẩu có cấu trúc | F8: Bảng companies: legal_name, registration_number, tax_id, country, industry_sector, founded_year, export_markets (N-N countries), languages_spoken, description_vi, description_en, website, logo; API CRUD + màn hình sửa. | G8: Mọi trường dùng để lọc/ghép là cột riêng, không nằm trong mô tả; lọc được qua API. | H8: 2.5 | I8: 0 | J8: GĐ1 · T1–2 · 29/9–12/10 | K8: T2 | L8: BE + FE | M8: A1 | N8: VYBE B1 | O8: Chưa bắt đầu
A9: B2 | B9: §5.2 · §4.2 | C9: P0 | D9: Hồ sơ | E9: Hồ sơ buyer có cấu trúc | F9: companies (type = buyer): industry, sourcing_categories (N-N nhóm hàng/HS), company_size, procurement_estimate, vat_number. | G9: Buyer lưu được nhóm hàng quan tâm; dùng được cho K1 và G2. | H9: 1.5 | I9: 0 | J9: GĐ1 · T1–2 · 29/9–12/10 | K9: T2 | L9: BE + FE | M9: A1 | N9: VYBE B2 | O9: Chưa bắt đầu
A10: B3 | B10: §5.2 | C10: P0 | D10: Hồ sơ | E10: Điểm hoàn thiện hồ sơ + danh sách còn thiếu | F10: Hàm tính profile_completeness_score theo bảng trọng số cấu hình được; API trả danh sách trường thiếu; hiện trên hồ sơ và dashboard. | G10: Điền thêm 1 trường thì % tăng đúng trọng số; danh sách thiếu khớp thực tế. | H10: 1 | I10: 0 | J10: GĐ1 · T1–2 · 29/9–12/10 | K10: T2 | L10: BE + FE | M10: B1 | N10: VYBE B3 | O10: Chưa bắt đầu
A11: B4 | B11: §4.2–4.3 · §5.3 | C11: P0 | D11: Hồ sơ | E11: Danh mục mã HS và nhóm hàng | F11: Bảng hs_codes (code 6–8 số, name_vi, name_en, chapter, is_calculator_supported); nhóm hàng ánh xạ theo chương HS; API gợi ý dùng pg_trgm + unaccent theo mã hoặc tên Việt/Anh. | G11: Gõ 'gạo', 'rice' hoặc '1006' đều gợi ý đúng mã; mã được hỗ trợ có cờ. | H11: 2 | I11: 0.5 | J11: GĐ1 · T1–2 · 29/9–12/10 | K11: T2 | L11: BE + FE | M11: C0 | N11: VYBE B4 — tag cũ Gold Supplier/OEM, không có mã HS | O11: Chưa bắt đầu
A12: B5 | B12: §4.3 | C12: P0 | D12: Hồ sơ | E12: Sản phẩm có cấu trúc | F12: Bảng products: hs_code (FK, bắt buộc), name, description_vi/en, price_min, price_max (numeric), currency, unit, moq, moq_unit, certifications (N-N evidences), images, is_active, approval_status. | G12: Không lưu được sản phẩm thiếu mã HS; hồ sơ công khai hiện đủ trường. | H12: 2 | I12: 0 | J12: GĐ1 · T1–2 · 29/9–12/10 | K12: T2 | L12: BE + FE | M12: B4 | N12: VYBE B5 | O12: Chưa bắt đầu
A13: C0 | B13: §5.3 · §9 · §10 | C13: P0 | D13: Tuân thủ | E13: Chốt danh mục HS hỗ trợ + người duyệt luật TM | F13: Chỉ định người duyệt; chốt 20 mã đợt đầu theo nhóm hàng SIAL, sau đó đủ 50 mã; quy ước mỗi dòng dữ liệu tuân thủ có người duyệt + ngày duyệt. | G13: Danh sách 20 mã đã ký trước 10/10; đủ 50 mã đã ký trước 9/11. | H13: 0 | I13: 1 | J13: GĐ1 · T1–2 · 29/9–12/10 | K13: T1 | L13: PO + Luật TM | M13: — | N13: VYBE C0 — điểm nghẽn của mọi hạng mục C và D | O13: Chưa bắt đầu
... A58: X8 | B58: — | C58: — | D58: Ngoài phạm vi | E58: AI đọc giấy tờ (AI Trust Co-pilot) | F58: Không chuyển sang evfta.eu trong MVP; cân nhắc sau tuần 12 nếu còn công, vì giúp duyệt nhanh hơn. | G58: — | H58: 0 | I58: 0 | J58: Sau MVP | K58: — | L58: — | M58: — | N58: VYBE X3 | O58: —

Sheet Mô hình dữ liệu
A1: Thực thể spec | B1: Bảng PostgreSQL | C1: Cột chính | D1: Ghi chú kỹ thuật | E1: Backlog | F1: Nguồn chuyển từ VYBE (J6)
A2: §4.1 User | B2: users | C2: id, email, phone, password_hash, role, preferred_language, consent_accepted_at, consent_version, created_at, last_login_at | D2: Argon2; email unique; role enum exporter/buyer/admin | E2: A1, J2 | F2: ApplicationUser (XAF Security)
A3: §4.2 Company | B3: companies | C3: id, owner_user_id, type, legal_name, country, registration_number, tax_id, industry_sector, verification_status, verification_level, verified_at, expires_at, profile_completeness_score, description_vi, description_en, website, logo_url | D3: Một bảng cho cả exporter và buyer, cột type; N-N export_markets, languages_spoken, sourcing_categories | E3: B1, B2, B3, I7 | F3: Company và Buyer; L0–L3 ánh xạ sang trạng thái + mức
A4: §4.3 Product | B4: products | C4: id, company_id, hs_code, name, description_vi, description_en, price_min, price_max, currency, unit, moq, moq_unit, images, is_active, approval_status | D4: Giá numeric; hs_code bắt buộc | E4: B5 | F4: Product
A5: §4.4 ComplianceCheck | B5: compliance_checks | C5: id, company_id (nullable), hs_code, product_value, origin_country, destination_country, mfn_duty_rate, evfta_duty_rate, savings_amount, regional_value_content_pct, originating_status, tariff_line_id, rule_id, created_at | D5: Append-only; ghi cả khách; tài sản dữ liệu | E5: C3 | F5: — (chưa có)
A6: §4.5 Document | B6: documents | C6: id, company_id, document_type, compliance_check_id, file_url, status, created_at | D6: File trên S3; chỉ sinh EUR.1 khi RoO = pass | E6: C5 | F6: — (chưa có)
A7: §4.6 VerificationRequest | B7: verification_requests, verification_decisions, evidences | C7: request: company_id, submitted_evidence_ids, status, submitted_at · decision: reviewer_id, decision, reason, decided_at · evidence: type, file, certificate_number, issuer, issued_at, expires_at, approval_status | D7: Lý do bắt buộc khi từ chối/yêu cầu bổ sung; bằng chứng xuất xứ hạn 12 tháng | E7: C6, I1, I2 | F7: Evidence + AiVerificationResult
A8: §4.7 Conversation / Message | B8: rfqs, conversations, messages | C8: rfq: product_id, quantity, unit, target_price, currency, incoterms, destination, required_date, status · message: conversation_id, sender_company_id, body_original, body_translated, original_language, translated_language, sent_at, read_at | D8: Mỗi RFQ mở một hội thoại | E8: F1, F2, F3 | F8: ContactRequest (chỉ RFQ)
A9: §4.8 SavedSearch | B9: saved_searches | C9: id, company_id, criteria (jsonb), created_at, last_notified_at | D9: jsonb chỉ cho tiêu chí | E9: K1, K2 | F9: — (chưa có)
A10: §4.9 Notification | B10: notifications | C10: id, user_id, type, payload (jsonb), link, is_read, created_at | D10: Loại: new_match, message, verification_status, expiry_alert, compliance_update | E10: H1, H2 | F10: — (chưa có)
A11: §4.10 AIQuery | B11: ai_queries | C11: id, user_id (nullable), question_text, answer_text, cited_sources, chunk_ids, confidence, model_version, was_helpful, escalated_to_human, created_at | D11: Append-only; ghi 100% câu hỏi | E11: D2, D3 | F11: — (AiVerificationResult là mục đích khác)
A12: §4.11 AuditLog | B12: audit_logs | C12: id, actor_id, action_type, entity_type, entity_id, before_state, after_state, created_at | D12: Append-only; không xóa khi xóa tài khoản (GDPR ẩn danh hóa) | E12: I6 | F12: XPO AuditTrail
... A15: Mới, ngoài spec | B15: profile_views, dashboard_events | C15: company_id, viewer_company_id, viewed_at · user_id, opened_at, had_new_info | D15: Phục vụ G1 và chỉ số 90% của G3 | E15: G1, G3 | F15: — (chưa có)

Sheet Lịch tuần
A1: Tuần | B1: Thời gian | C1: Mốc | D1: BE Python (2) | E1: FE Next.js (2) | F1: AI (50% từ T5) | G1: QA (từ T3) | H1: Luật TM | I1: PO | J1: VYBE (Duy Tân)
A2: T1 | B2: 29/9–5/10 | C2: Chốt người luồng B và luật TM | D2: J7, A1, I6 | E2: A0, A3 | F2: — | G2: — | H2: C0, bắt đầu D0 | I2: Chốt quyết định tuần 1 | J2: A1, I2, I3 sửa gấp
A3: T2 | B3: 6/10–12/10 | C3: CI/CD + staging chạy; đăng ký → hồ sơ nháp | D3: A1, B1, B2, B3, B4, B5, C1 (bảng) | E3: A2, B1–B5 (giao diện), A3 | F3: — | G3: — | H3: Duyệt 20 mã HS; nhập dòng thuế C1; D0 | I3: J5 dữ liệu demo | J3: Launch VYBE v1: 10/10
A4: T3 | B4: 13/10–19/10 | C4: 20 dòng thuế đã duyệt | D4: C3, J1, C2 (API) | E4: C2 (giao diện) | F4: — | G4: Test chuẩn C2 | H4: Duyệt C1; D0 | I4: Chuẩn bị SIAL | J4: Đóng băng 15/10
A5: T4 | B5: 20/10–26/10 | C5: Máy tính thuế chạy trên staging | D5: C2, C4 (bảng quy tắc) | E5: C2, C4 (giao diện) | F5: — | G5: Test C2, C4 | H5: Soạn 10 ca kiểm C4; D0 | I5: Thu phản hồi SIAL | J5: SIAL 17–21/10; đóng băng tính năng 22/10
A6: T5 | B6: 27/10–2/11 | C6: Quy tắc xuất xứ 20 mã | D6: C4, I7, I1, C6 | E6: I1, C6 | F6: Nhận bàn giao D0 | G6: Test C4 (10 ca) | H6: Duyệt C4; D0 | I6: — | J6: Chỉ sửa lỗi
A7: T6 | B7: 3/11–9/11 | C7: Đủ 50 mã; duyệt hồ sơ dưới 5 phút | D7: C5, I2, H2, I4, I5 | E7: I2, I4, I5 | F7: D1 cắt đoạn + nhúng | G7: Test C5, I2 | H7: Duyệt 50 mã; soạn 50 câu | I7: — | J7: Chỉ sửa lỗi
A8: T7 | B8: 10/11–16/11 | C8: Pipeline truy xuất chạy | D8: Hỗ trợ API D2 | E8: D2 (giao diện /copilot) | F8: D1, D4, D2 | G8: Chạy bộ 50 câu lần 1 | H8: Chấm bộ 50 câu | I8: — | J8: —
A9: T8 | B9: 17/11–23/11 | C9: Bộ 50 câu đạt ngưỡng luật TM ký | D9: D3, I5 (chỉ số AI) | E9: D3 (màn hình admin) | F9: D2 sửa theo kết quả | G9: Chạy lại bộ 50 câu | H9: Ký ngưỡng | I9: — | J9: —
A10: T9 | B10: 24/11–30/11 | C10: Danh bạ công khai + RFQ | D10: E1, E2, F1, H1 | E10: E2, E3, E4, F1, H1 | F10: Theo dõi câu tin cậy thấp | G10: Test E, F1 | H10: Soát mẫu AI tuần | I10: Onboarding doanh nghiệp thật | J10: —
A11: T10 | B11: 1/12–7/12 | C11: Vòng RFQ Việt–Anh hoàn tất; chạy thử chuyển dữ liệu | D11: F2, F3, K1, K2, J2, H2 (phần còn lại), J6 (chạy thử) | E11: F2, K1 | F11: — | G11: Test F2, F3, K | H11: Soát mẫu AI tuần | I11: Onboarding | J11: Cung cấp dump dữ liệu
A12: T11 | B12: 8/12–14/12 | C12: Dashboard hai vai trò | D12: G1, G2, G3 | E12: G1, G2, J3, A3 (rà chuỗi) | F12: — | G12: J3 trên 390px | H12: — | I12: Ký pilot | J12: —
A13: T12 | B13: 15/12–21/12 | C13: MVP hoàn tất theo spec §11 | D13: J6 (chạy thật), J8, sửa lỗi | E13: Sửa lỗi | F13: — | G13: J4, J8 | H13: — | I13: 50–100 doanh nghiệp, 2–3 pilot | J13: Tắt VYBE hoặc chuyển hướng
